package com.d01.exception;

public class ExceptionMain03 {
	public static void main(String[] args) {
		//다주 catch문 사용
		
		int var = 50;
		try {
			//예외가 발생할 가능성이 있는 코드
			//               String -> int
//			args[0] = "10";
			int data = Integer.parseInt(args[0]);
//			                                                    외부에서 받아오는 값
			System.out.println(var/data);
			
			//*주의* 다중 catch무늘 사용 할 때
			//Exception과 하위 예외 클래스를 동시에
			//명시할 때는 하위 예외 클래스를 먼저 명시하고
			//가장 뒤에 Exception을 명시해야 동작상의 문제가 발생하지 않음
		}
		
		catch (NumberFormatException e) {
			// TODO: handle exception
			System.out.println("숫자가 아닙니다.");
		}catch (ArrayIndexOutOfBoundsException e) {
			// TODO: handle exception
			System.out.println("입력한 데이터가 없습니다.");
		}catch (ArithmeticException e) {
			// TODO: handle exception
			System.out.println("0으로 나눌 수 없습니다.");
		}
		catch (Exception e) {
			// TODO: handle exception
			System.out.println("예외가 발생했습니다.");
		}
		System.out.println("프로그램 종료");
	}

}
